[2024-07-18 06:35:37,828] {taskinstance.py:851} INFO - Dependencies all met for <TaskInstance: xcom_example_dag.pull_task 2024-04-10T00:00:00+00:00 [queued]>
[2024-07-18 06:35:38,032] {taskinstance.py:851} INFO - Dependencies all met for <TaskInstance: xcom_example_dag.pull_task 2024-04-10T00:00:00+00:00 [queued]>
[2024-07-18 06:35:38,033] {taskinstance.py:1042} INFO - 
--------------------------------------------------------------------------------
[2024-07-18 06:35:38,034] {taskinstance.py:1043} INFO - Starting attempt 1 of 2
[2024-07-18 06:35:38,045] {taskinstance.py:1044} INFO - 
--------------------------------------------------------------------------------
[2024-07-18 06:35:38,205] {taskinstance.py:1063} INFO - Executing <Task(PythonOperator): pull_task> on 2024-04-10T00:00:00+00:00
[2024-07-18 06:35:38,273] {standard_task_runner.py:52} INFO - Started process 3116 to run task
[2024-07-18 06:35:38,320] {standard_task_runner.py:76} INFO - Running: ['airflow', 'tasks', 'run', 'xcom_example_dag', 'pull_task', '2024-04-10T00:00:00+00:00', '--job-id', '562', '--pool', 'default_pool', '--raw', '--subdir', 'DAGS_FOLDER/xcom.py', '--cfg-path', '/tmp/tmpsiczn1bf', '--error-file', '/tmp/tmpvy36t2ms']
[2024-07-18 06:35:38,369] {standard_task_runner.py:77} INFO - Job 562: Subtask pull_task
[2024-07-18 06:35:38,830] {logging_mixin.py:104} INFO - Running <TaskInstance: xcom_example_dag.pull_task 2024-04-10T00:00:00+00:00 [running]> on host a868c7bacc12
[2024-07-18 06:35:39,298] {taskinstance.py:1257} INFO - Exporting the following env vars:
AIRFLOW_CTX_DAG_OWNER=airflow
AIRFLOW_CTX_DAG_ID=xcom_example_dag
AIRFLOW_CTX_TASK_ID=pull_task
AIRFLOW_CTX_EXECUTION_DATE=2024-04-10T00:00:00+00:00
AIRFLOW_CTX_DAG_RUN_ID=scheduled__2024-04-10T00:00:00+00:00
[2024-07-18 06:35:39,541] {local_task_job.py:77} ERROR - Received SIGTERM. Terminating subprocesses
[2024-07-18 06:35:39,676] {logging_mixin.py:104} INFO - Pulled message: Hello from push_function!
[2024-07-18 06:35:39,706] {python.py:118} INFO - Done. Returned value was: None
[2024-07-18 06:35:39,763] {process_utils.py:100} INFO - Sending Signals.SIGTERM to GPID 3116
[2024-07-18 06:35:39,776] {taskinstance.py:1239} ERROR - Received SIGTERM. Terminating subprocesses.
[2024-07-18 06:35:39,832] {taskinstance.py:1455} ERROR - Task received SIGTERM signal
Traceback (most recent call last):
  File "/home/airflow/.local/lib/python3.6/site-packages/airflow/models/taskinstance.py", line 1113, in _run_raw_task
    self.refresh_from_db(lock_for_update=True)
  File "/home/airflow/.local/lib/python3.6/site-packages/airflow/utils/session.py", line 65, in wrapper
    return func(*args, session=session, **kwargs)
  File "/home/airflow/.local/lib/python3.6/site-packages/airflow/models/taskinstance.py", line 579, in refresh_from_db
    ti = qry.with_for_update().first()
  File "/home/airflow/.local/lib/python3.6/site-packages/sqlalchemy/orm/query.py", line 3429, in first
    ret = list(self[0:1])
  File "/home/airflow/.local/lib/python3.6/site-packages/sqlalchemy/orm/query.py", line 3203, in __getitem__
    return list(res)
  File "/home/airflow/.local/lib/python3.6/site-packages/sqlalchemy/orm/query.py", line 3535, in __iter__
    return self._execute_and_instances(context)
  File "/home/airflow/.local/lib/python3.6/site-packages/sqlalchemy/orm/query.py", line 3557, in _execute_and_instances
    querycontext, self._connection_from_session, close_with_result=True
  File "/home/airflow/.local/lib/python3.6/site-packages/sqlalchemy/orm/query.py", line 3572, in _get_bind_args
    mapper=self._bind_mapper(), clause=querycontext.statement, **kw
  File "/home/airflow/.local/lib/python3.6/site-packages/sqlalchemy/orm/query.py", line 3550, in _connection_from_session
    conn = self.session.connection(**kw)
  File "/home/airflow/.local/lib/python3.6/site-packages/sqlalchemy/orm/session.py", line 1145, in connection
    execution_options=execution_options,
  File "/home/airflow/.local/lib/python3.6/site-packages/sqlalchemy/orm/session.py", line 1151, in _connection_for_bind
    engine, execution_options
  File "/home/airflow/.local/lib/python3.6/site-packages/sqlalchemy/orm/session.py", line 433, in _connection_for_bind
    conn = bind._contextual_connect()
  File "/home/airflow/.local/lib/python3.6/site-packages/sqlalchemy/engine/base.py", line 2302, in _contextual_connect
    self._wrap_pool_connect(self.pool.connect, None),
  File "/home/airflow/.local/lib/python3.6/site-packages/sqlalchemy/engine/base.py", line 2336, in _wrap_pool_connect
    return fn()
  File "/home/airflow/.local/lib/python3.6/site-packages/sqlalchemy/pool/base.py", line 364, in connect
    return _ConnectionFairy._checkout(self)
  File "/home/airflow/.local/lib/python3.6/site-packages/sqlalchemy/pool/base.py", line 778, in _checkout
    fairy = _ConnectionRecord.checkout(pool)
  File "/home/airflow/.local/lib/python3.6/site-packages/sqlalchemy/pool/base.py", line 495, in checkout
    rec = pool._do_get()
  File "/home/airflow/.local/lib/python3.6/site-packages/sqlalchemy/pool/impl.py", line 241, in _do_get
    return self._create_connection()
  File "/home/airflow/.local/lib/python3.6/site-packages/sqlalchemy/pool/base.py", line 309, in _create_connection
    return _ConnectionRecord(self)
  File "/home/airflow/.local/lib/python3.6/site-packages/sqlalchemy/pool/base.py", line 440, in __init__
    self.__connect(first_connect_check=True)
  File "/home/airflow/.local/lib/python3.6/site-packages/sqlalchemy/pool/base.py", line 661, in __connect
    pool.logger.debug("Error on connect(): %s", e)
  File "/home/airflow/.local/lib/python3.6/site-packages/sqlalchemy/util/langhelpers.py", line 70, in __exit__
    with_traceback=exc_tb,
  File "/home/airflow/.local/lib/python3.6/site-packages/sqlalchemy/util/compat.py", line 182, in raise_
    raise exception
  File "/home/airflow/.local/lib/python3.6/site-packages/sqlalchemy/pool/base.py", line 656, in __connect
    connection = pool._invoke_creator(self)
  File "/home/airflow/.local/lib/python3.6/site-packages/sqlalchemy/engine/strategies.py", line 114, in connect
    return dialect.connect(*cargs, **cparams)
  File "/home/airflow/.local/lib/python3.6/site-packages/sqlalchemy/engine/default.py", line 508, in connect
    return self.dbapi.connect(*cargs, **cparams)
  File "/home/airflow/.local/lib/python3.6/site-packages/psycopg2/__init__.py", line 127, in connect
    conn = _connect(dsn, connection_factory=connection_factory, **kwasync)
  File "/home/airflow/.local/lib/python3.6/site-packages/airflow/models/taskinstance.py", line 1241, in signal_handler
    raise AirflowException("Task received SIGTERM signal")
airflow.exceptions.AirflowException: Task received SIGTERM signal
[2024-07-18 06:35:39,891] {taskinstance.py:1503} INFO - Marking task as UP_FOR_RETRY. dag_id=xcom_example_dag, task_id=pull_task, execution_date=20240410T000000, start_date=20240718T063537, end_date=20240718T063539
[2024-07-18 06:35:40,130] {process_utils.py:66} INFO - Process psutil.Process(pid=3116, status='terminated', exitcode=1, started='06:35:37') (3116) terminated with exit code 1
